Workbook

Sheet Objekte
A1: Ordnungsnummer | B1: Name | C1: Link Objekt (URL) | D1: Charme/Ästhetik (1-5) | E1: Zimmer | F1: Bäder | G1: Grundstücksgröße (m²) | H1: Bebaute Fläche (m²) | I1: Garten zu bewirtschaften (m²) | J1: Location | K1: Entfernung Flughafen (km) | L1: Entfernung Flughafen (min) | M1: Entfernung Daia Haus (km) | N1: Entfernung Daia Haus (min) | O1: Entfernung Andratx (km) | P1: Entfernung Andratx (min) | Q1: Entfernung Ses Salines (km) | R1: Entfernung Ses Salines (min) | S1: Preis (€) | T1: €/m² (bebaut) | U1: €/m² (Grundstück) | V1: Renovierung (0-100) | W1: Bewirtschaftung (1-5, 5=pflegeleicht) | X1: Vermietlizenz (100/50/0) | Y1: Erreichbarkeit (0-100) | Z1: Score (0-100) | AA1: SortKey (intern) | AB1: Rang | AC1: Gebäudestruktur | AD1: Baujahr (geschätzt) | AE1: Letzte Renovierung (geschätzt) | AF1: Reno-Score (0-100) | AG1: Reno-Begründung | AH1: Kommentar | AI1: Beschreibung
A2: 1 | B2: Establiments — Das Volumen; 762m² zum Umdenken | C2: https://www.idealista.com/de/inmueble/106332052/mapa?utm_medium=socialmedia&utm_campaign=private_sendadtofriend&utm_source=copiedLink | D2: 4 | E2: 4 | F2: 5 | G2: 20262 | H2: 762 | I2: 19500 | J2: Establiments | K2: 16.5 | L2: 20 | M2: 30.5 | N2: 39 | O2: 34.1 | P2: 35 | Q2: 59.4 | R2: 53 | S2: 3600000 | T2: 4724 | U2: 178 | V2: 70 | W2: 3 | X2: 0 | Y2: 58.5 | Z2: 50 | AA2: 5.0020263e+13 | AB2: 6 | AC2: Haupthaus (2 Stockwerke + Turm), große Terrassen | AD2: ~1960s | AE2: ~2022 | AF2: 70 | AG2: Traditional country house, fully renovated with high-end kitchen (Gaggenau/Bora), modern open-plan layout. No build year listed suggests older structure. Excel comment notes 'Haupthaus (2 Stockwerke + Turm), große Terrassen'. Well-renovated but original structure is old. Old=4 → 70. | AI2: Riesig, tolle Lage — aber nur 4 Zimmer. Umbau nötig, dann ein Monster.
A3: 2 | B3: Binissalem — Platz für alle; 8 Zimmer, endlose Gärten | C3: https://www.engelvoelkers.com/es/de/exposes/6971ac2a-f182-5703-a001-2c6f306cd2ae?utm_source=expose_sharing&utm_medium=copy_link | D3: 4 | E3: 8 | F3: 6 | G3: 8261 | H3: 400 | I3: 7861 | J3: Binissalem | K3: 29 | L3: 24 | M3: 36.2 | N3: 42 | O3: 51.6 | P3: 42 | Q3: 71.9 | R3: 57 | S3: 3400000 | T3: 8500 | U3: 412 | V3: 72 | W3: 3 | X3: 0 | Y3: 49.3 | Z3: 57.5 | AA3: 5.7508261e+13 | AB3: 3 | AC3: Haupthaus + 2 separate Gästehäuser | AD3: 2002 | AE3: ~2022 | AF3: 72 | AG3: Built 2002, comprehensively modernized with PV, Starlink, modern insulation. Condition rated 'Sehr gut'. Only 23 years old with full modernization. Excel: 'Sehr schön, evtl. Ausbaumöglichkeit'. Old=4 → 72. | AH3: Sehr schön, evtl. Ausbaumöglichkeit für zusätzliches Zimmer prüfen | AI3: Sommer im Garten, Großmutter zum Abendessen — alles nah, alles einfach.
A4: 3 | B4: Establiments — Charme-Refugium; altes Steinhaus mit Charakter | C4: https://www.idealista.com/de/inmueble/106744049/foto/1/?utm_medium=socialmedia&utm_campaign=private_sendadtofriend&utm_source=copiedLink | D4: 5 | E4: 7 | F4: 7 | G4: 14393 | H4: 601 | I4: 13792 | J4: Establiments | K4: 16.5 | L4: 20 | M4: 30.5 | N4: 39 | O4: 34.1 | P4: 35 | Q4: 59.4 | R4: 53 | S4: 4500000 | T4: 7488 | U4: 313 | V4: 62 | W4: 2 | X4: 0 | Y4: 58.5 | Z4: 58.6 | AA4: 5.8614394e+13 | AB4: 2 | AC4: Haupthaus (5 SZ, 6 Bäder) + unabhängiges Gästehaus (2 SZ, 1 Bad) | AD4: 1980 | AE4: ~2015 | AF4: 62 | AG4: Built 1980 (45 years old), maintained in Mallorcan country house style with modern amenities (underfloor heating, designer kitchen). Excel: 'Gute Raumanzahl + Gästehaus, innen nicht ganz überzeugend'. Interior not fully convincing suggests renovation is partial. Old=4 → 62. | AH4: Gute Raumanzahl + Gästehaus, innen nicht ganz überzeugend | AI4: Alte Mauern, warmes Licht — ein Haus das die Kinder nie vergessen werden.
A5: 4 | B5: Palmanyola — Klein aber Wow; Designvilla vor den Toren Palmas | C5: https://www.idealista.com/de/inmueble/109708161/plano/2/?utm_medium=socialmedia&utm_campaign=private_sendadtofriend&utm_source=copiedLink | D5: 4 | E5: 5 | F5: 5 | G5: 2500 | H5: 670 | I5: 1830 | J5: Palmanyola | K5: 16.6 | L5: 16 | M5: 18 | N5: 23 | O5: 36.2 | P5: 32 | Q5: 59.5 | R5: 50 | S5: 5600000 | T5: 8358 | U5: 2240 | V5: 78 | W5: 4 | X5: 0 | Y5: 76 | Z5: 31.3 | AA5: 3.1302501e+13 | AB5: 12 | AC5: Freistehendes Haus mit Pool und Garten | AD5: ~1990s | AE5: ~2024 | AF5: 78 | AG5: Description explicitly says 'komplett kernsaniert' – complete core renovation. Modern open kitchen, fireplace, 2 floors with 670m². Excel old=3 probably reflected pre-renovation state or plot size concern ('Grundstück evtl. zu klein'). Actual condition is excellent post-renovation. → 78. | AH5: Sehr modern, Grundstück evtl. zu klein | AI5: Modern, sofort bezugsfertig, nah dran — aber Grundstück zu klein für drei Kinder.
A6: 5 | B6: Santa Maria — Potenzial pur; Rohling in Traumlage | C6: https://www.idealista.com/de/inmueble/106300856/foto/17/?utm_medium=socialmedia&utm_campaign=private_sendadtofriend&utm_source=copiedLink | D6: 4 | E6: 5 | F6: 5 | G6: 29307 | H6: 500 | I6: 28807 | J6: Santa Maria del Cami | K6: 21 | L6: 16 | M6: 24.2 | N6: 32 | O6: 43.6 | P6: 34 | Q6: 63.8 | R6: 49 | S6: 4100000 | T6: 8200 | U6: 140 | V6: 48 | W6: 3 | X6: 0 | Y6: 66 | Z6: 43.5 | AA6: 4.3529308e+13 | AB6: 10 | AC6: Landhaus mit Pool und Terrassen, teils unfertig | AD6: 2024 | AE6: n/a (new build) | AF6: 48 | AG6: New build 2024 but still under construction ('In Bearbeitung'). Excel: 'Gute Lage, einiges noch nicht fertig'. While the finished product will be new, incomplete status means uncertain timeline and finishing quality. Old=3 → 48. | AH6: Gute Lage, einiges noch nicht fertig | AI6: Traumlage, nah am Flughafen — aber unfertig. Mit kleinen Kindern erstmal stressig.
A7: 6 | B7: Campos — Zum Selbermachen; ehrliche Finca, ehrlicher Preis | C7: https://www.idealista.com/de/inmueble/81539590/?utm_medium=socialmedia&utm_campaign=private_sendadtofriend&utm_source=copiedLink | D7: 4 | E7: 6 | F7: 5 | G7: 11700 | H7: 356 | I7: 11344 | J7: Campos | K7: 29.9 | L7: 21 | M7: 64.2 | N7: 57 | O7: 67.9 | P7: 50 | Q7: 12.2 | R7: 13 | S7: 2850000 | T7: 8006 | U7: 244 | V7: 50 | W7: 3 | X7: 0 | Y7: 57.8 | Z7: 44 | AA7: 4.40117e+13 | AB7: 9 | AC7: Modernes Landhaus mit großem Pool und Garten | AD7: ~1990s | AE7: ~2010 | AF7: 50 | AG7: No build year, 'In Bearbeitung' status, no heating system. Excel: 'Interessante Substanz, viel Interior-Arbeit, evtl. günstiger'. Needs significant interior renovation work. Good bones but unfinished. Old=4 seems generous; actual condition warrants 50. | AH7: Interessante Substanz, viel Interior-Arbeit, evtl. günstiger | AI7: Solide Basis, fairer Preis — aber hier muss noch Hand angelegt werden.
A8: 7 | B8: Sa Ràpita — Strandgold; aufwachen, Es Trenc, fertig | C8: https://www.idealista.com/de/inmueble/109467637/foto/18/?utm_medium=socialmedia&utm_campaign=private_sendadtofriend&utm_source=copiedLink | D8: 4 | E8: 5 | F8: 5 | G8: 30000 | H8: 533 | I8: 29467 | J8: Sa Ràpita | K8: 35 | L8: 28 | M8: 69.4 | N8: 64 | O8: 73.1 | P8: 58 | Q8: 14.9 | R8: 17 | S8: 3950000 | T8: 7411 | U8: 132 | V8: 68 | W8: 2 | X8: 0 | Y8: 42 | Z8: 37.4 | AA8: 3.7430001e+13 | AB8: 11 | AC8: Haupthaus mit ausgedehntem Grundstück und Pool | AD8: 2024 | AE8: n/a (new build) | AF8: 68 | AG8: New build 2024 with modern design and natural elements. 30,000m² plot near Es Trenc beach. No 'In Bearbeitung' flag suggests more complete than Santa Maria property. Excel old=3 seems low for a 2024 new build; possibly reflected other concerns. → 68. | AH8: Nähe Es Trenc | AI8: Strand vor der Tür, perfekt für Sommer — aber über eine Stunde zum Familienhaus.
A9: 8 | B9: Sa Ràpita — Vision 1800; 5 Hektar warten auf deine Handschrift | C9: https://www.idealista.com/de/inmueble/106134268/video/1/?utm_medium=socialmedia&utm_campaign=private_sendadtofriend&utm_source=copiedLink | D9: 3 | E9: 6 | F9: 3 | G9: 51000 | H9: 680 | I9: 50320 | J9: Sa Ràpita | K9: 35 | L9: 28 | M9: 69.4 | N9: 64 | O9: 73.1 | P9: 58 | Q9: 14.9 | R9: 17 | S9: 2950000 | T9: 4338 | U9: 58 | V9: 30 | W9: 4 | X9: 0 | Y9: 42 | Z9: 49.3 | AA9: 4.9351001e+13 | AB9: 7 | AC9: Haus mit Pool in ruhiger Lage | AD9: 1800 | AE9: unknown | AF9: 30 | AG9: Built around 1800 – over 200 years old. 'In Bearbeitung' and Excel says 'Hier könnte sich Mathieu verwirklichen' (creative project). Traditional Mallorcan farmhouse needing significant work. Described as 'gut erhalten' (well-maintained) but very old. Old=3 → 30. | AH9: Hier könnte sich Mathieu verwirklichen 😉 | AI9: Für Visionäre — aber nichts für 6 Wochen im Jahr. Ehrlich gesagt: zu viel Projekt.
A10: 9 | B10: Sencelles — 13 Hektar Paradies; dein eigenes Landgut | C10: https://ev-mallorca.com/en/mallorca-property/excellent-estate-with-its-own-vineyard-olive-grove-and-incredible-charm-W-02Q8YG | D10: 5 | E10: 6 | F10: 5 | G10: 132500 | H10: 682 | I10: 131818 | J10: Sencelles | K10: 31.7 | L10: 26 | M10: 38.9 | N10: 44 | O10: 54.3 | P10: 45 | Q10: 44 | R10: 45 | S10: 3900000 | T10: 5718 | U10: 29 | V10: 85 | W10: 2 | X10: 50 | Y10: 44.8 | Z10: 59.8 | AA10: 5.9932501e+13 | AB10: 1 | AC10: Haupthaus + Gästeapartment + Studio, Weinberg & Olivenhain | AD10: 1890 | AE10: ~2020 | AF10: 85 | AG10: Built 1890 but rated neuwertig (5) in Excel. Must have undergone comprehensive luxury renovation. 132,000m²+ estate with vineyard and olive grove. The 'incredible charm' title plus neuwertig rating suggests top-quality restoration. Historic character + modern luxury. → 85. | AI10: So viel Platz, dass sich drei kleine Entdecker darin verlaufen können.
A11: 10 | B11: Ses Salines — Neubau Deluxe; einziehen und leben | C11: https://ev-mallorca.com/en/mallorca-property/unique-designer-house-in-a-quiet-location-W-0475DS | D11: 5 | E11: 5 | F11: 5 | G11: 23800 | H11: 399 | I11: 23401 | J11: Ses Salines | K11: 42.2 | L11: 34 | M11: 76.5 | N11: 70 | O11: 80.2 | P11: 63 | Q11: 0 | R11: 0 | S11: 5450000 | T11: 13659 | U11: 229 | V11: 98 | W11: 4 | X11: 0 | Y11: 33.3 | Z11: 31 | AA11: 3.10238e+13 | AB11: 13 | AC11: Einzelgebäude (einstöckig), Neubau 2025 | AD11: 2025 | AE11: n/a (new build) | AF11: 98 | AG11: Brand new construction 2025. Designer house, single-story, quiet location. As new as it gets. Old=5 → 98. | AI11: Koffer abstellen, fertig. Aber weit vom Familienhaus und über Budget.
A12: 11 | B12: Moscari — Architekten-Traum; Design trifft Serra de Tramuntana | C12: https://ev-mallorca.com/en/mallorca-property/where-contemporary-design-blends-in-perfect-harmony-with-the-mediterranean-landscape-W-02NQDS | D12: 5 | E12: 5 | F12: 5 | G12: 19811 | H12: 832 | I12: 18979 | J12: Moscari | K12: 46.3 | L12: 34 | M12: 53.5 | N12: 52 | O12: 68.9 | P12: 52 | Q12: 64.6 | R12: 62 | S12: 3950000 | T12: 4748 | U12: 199 | V12: 92 | W12: 4 | X12: 0 | Y12: 29.3 | Z12: 48.8 | AA12: 4.8819812e+13 | AB12: 8 | AC12: Haupthaus + separater Gästebereich | AD12: 2018 | AE12: n/a | AF12: 92 | AG12: Built 2018, only 8 years old. Contemporary design, large 832m² living area. Wheelchair accessible and senior-oriented suggests high-spec modern build. Excel: 'Haupthaus + separater Gästebereich'. Old=5 → 92. | AI12: Aufwachen mit Bergblick, einschlafen mit Stille — aber weit weg vom Familienhaus.
A13: 12 | B13: Campos — Finca mit Lizenz; 14 Hektar mallorquinischer Traum | C13: https://ev-mallorca.com/en/mallorca-property/dreamlike-finca-with-rental-license-near-es-trenc-W-02ZICD | D13: 4 | E13: 6 | F13: 6 | G13: 14200 | H13: 436 | I13: 13764 | J13: Campos | K13: 30.6 | L13: 23 | M13: 64.2 | N13: 57 | O13: 67.9 | P13: 50 | Q13: 12.2 | R13: 13 | S13: 3490000 | T13: 8005 | U13: 246 | V13: 65 | W13: 2 | X13: 100 | Y13: 56.2 | Z13: 54.4 | AA13: 5.44142e+13 | AB13: 4 | AC13: Haupthaus + separater Gebäudeteil (L-Form), Sportanlagen | AD13: 1997 | AE13: 2014 | AF13: 65 | AG13: Built 1997, last restored 2014 (12 years ago). Well-equipped with PV, underfloor heating, A/C. Sports facilities. But restoration is over a decade old now. Excel: 'Haupthaus + separater Gebäudeteil (L-Form), Sportanlagen'. Old=4 → 65. | AI13: Vermieten wenn ihr nicht da seid, ankommen wenn ihr wollt — die Finca rechnet sich.
A14: 13 | B14: Bunyola — Berglage mit Lizenz; Tramuntana vor der Tür | C14: https://www.idealista.com/inmueble/110322709/ | D14: 5 | E14: 6 | F14: 5 | G14: 14785 | H14: 355 | J14: Bunyola | K14: 23.8 | L14: 20 | M14: 14.8 | N14: 20 | O14: 46.4 | P14: 38 | Q14: 66.7 | R14: 53 | S14: 3500000 | T14: 9859 | U14: 237 | V14: 70 | W14: 3 | X14: 100 | Y14: 76 | Z14: 51.2 | AA14: 5.1214785e+13 | AB14: 5 | AC14: Haupthaus + Gästehaus (70m²) + Turm (30m²) | AD14: 2008 | AE14: unknown | AF14: 70 | AG14: Built 2008 (18 years old), good condition ('buen estado'). Single-story, 6 rooms, 5 baths. Excel: 'Haupthaus + Gästehaus (70m²) + Turm (30m²)'. Solid build age with good condition rating. Old=4 → 70. | AI14: 20 Minuten zum Familienhaus, Berge vor der Tür, Gäste im Haus — alles gleichzeitig.
A15: 14 | D15: 5 | T15: =IFERROR(IF($Q15="","",$Q15/$H15),"") | U15: =IFERROR(IF($Q15="","",$Q15/$G15),"") | V15: 4 | W15: 3 | Y15: =IF(AND($L15="",$N15="",$P15=""),"",ROUND((IF($L15="",0,IF($L15<=Einstellungen!$B$16,100,IF($L15<=Einstellungen!$C$16,80+(100-80)*(Einstellungen!$C$16-$L15)/(Einstellungen!$C$16-Einstellungen!$B$16),IF($L15<=Einstellungen!$D$16,80*(Einstellungen!$D$16-$L15)/(Einstellungen!$D$16-Einstellungen!$C$16),0))))*Einstellungen!$E$16+IF($N15="",0,IF($N15<=Einstellungen!$B$17,100,IF($N15<=Einstellungen!$C$17,80+(100-80)*(Einstellungen!$C$17-$N15)/(Einstellungen!$C$17-Einstellungen!$B$17),IF($N15<=Einstellungen!$D$17,80*(Einstellungen!$D$17-$N15)/(Einstellungen!$D$17-Einstellungen!$C$17),0))))*Einstellungen!$E$17+IF($P15="",0,IF($P15<=Einstellungen!$B$18,100,IF($P15<=Einstellungen!$C$18,80+(100-80)*(Einstellungen!$C$18-$P15)/(Einstellungen!$C$18-Einstellungen!$B$18),IF($P15<=Einstellungen!$D$18,80*(Einstellungen!$D$18-$P15)/(Einstellungen!$D$18-Einstellungen!$C$18),0))))*Einstellungen!$E$18)/(Einstellungen!$E$16+Einstellungen!$E$17+Einstellungen!$E$18),0)) | Z15: =IF(AND($E15="",$D15="",$G15="",$V15="",$Q15="",$T15="",$W15="",$U15=""),"",ROUND(IF($E15="",0,IF($E15<Einstellungen!$B$21,0,IF($E15>=Einstellungen!$B$22,100,($E15-Einstellungen!$B$21)/(Einstellungen!$B$22-Einstellungen!$B$21)*100)))/100*Einstellungen!$B$5+IF($W15="",0,$W15/100)*Einstellungen!$B$6+(IF($G15="",0,MAX(0,MIN(100,($G15-Einstellungen!$B$25)/(Einstellungen!$B$26-Einstellungen!$B$25)*100)))+IF($I15="",0,MAX(0,MIN(100,($I15-Einstellungen!$B$27)/(Einstellungen!$B$28-Einstellungen!$B$27)*100))))/2/100*Einstellungen!$B$7+IF($V15="",0,$V15/100)*Einstellungen!$B$8+IF($R15="",0,MAX(0,MIN(100,(Einstellungen!$B$32-$R15)/(Einstellungen!$B$32-Einstellungen!$B$31)*100)))/100*Einstellungen!$B$9+IF($D15="",0,$D15/5*100)/100*Einstellungen!$B$10+IF($AD15="",0,$AD15)/100*Einstellungen!$B$11+IF($U15="",0,$U15/5*100)/100*Einstellungen!$B$12,0)) | AA15: =IF($X15="","",$X15*1000000000000+IF($G15="",0,$G15)*1000000+IF($H15="",0,$H15)*1000+IF($I15="",0,$I15)+IF($N15="",0,MAX(0,1000-$N15))/1000+IF($A15="",0,$A15)/1000000) | AB15: =IF($Y15="","",_xludf.RANK.EQ($Y15,$Y$2:$Y$201,0)) | AC15: Unabhängiges Chalet mit Pool und Bergblick
T16: =IFERROR(IF($Q16="","",$Q16/$H16),"") | U16: =IFERROR(IF($Q16="","",$Q16/$G16),"") | Y16: =IF(AND($L16="",$N16="",$P16=""),"",ROUND((IF($L16="",0,IF($L16<=Einstellungen!$B$16,100,IF($L16<=Einstellungen!$C$16,80+(100-80)*(Einstellungen!$C$16-$L16)/(Einstellungen!$C$16-Einstellungen!$B$16),IF($L16<=Einstellungen!$D$16,80*(Einstellungen!$D$16-$L16)/(Einstellungen!$D$16-Einstellungen!$C$16),0))))*Einstellungen!$E$16+IF($N16="",0,IF($N16<=Einstellungen!$B$17,100,IF($N16<=Einstellungen!$C$17,80+(100-80)*(Einstellungen!$C$17-$N16)/(Einstellungen!$C$17-Einstellungen!$B$17),IF($N16<=Einstellungen!$D$17,80*(Einstellungen!$D$17-$N16)/(Einstellungen!$D$17-Einstellungen!$C$17),0))))*Einstellungen!$E$17+IF($P16="",0,IF($P16<=Einstellungen!$B$18,100,IF($P16<=Einstellungen!$C$18,80+(100-80)*(Einstellungen!$C$18-$P16)/(Einstellungen!$C$18-Einstellungen!$B$18),IF($P16<=Einstellungen!$D$18,80*(Einstellungen!$D$18-$P16)/(Einstellungen!$D$18-Einstellungen!$C$18),0))))*Einstellungen!$E$18)/(Einstellungen!$E$16+Einstellungen!$E$17+Einstellungen!$E$18),0)) | Z16: =IF(AND($E16="",$D16="",$G16="",$V16="",$Q16="",$T16="",$W16="",$U16=""),"",ROUND(IF($E16="",0,IF($E16<Einstellungen!$B$21,0,IF($E16>=Einstellungen!$B$22,100,($E16-Einstellungen!$B$21)/(Einstellungen!$B$22-Einstellungen!$B$21)*100)))/100*Einstellungen!$B$5+IF($W16="",0,$W16/100)*Einstellungen!$B$6+(IF($G16="",0,MAX(0,MIN(100,($G16-Einstellungen!$B$25)/(Einstellungen!$B$26-Einstellungen!$B$25)*100)))+IF($I16="",0,MAX(0,MIN(100,($I16-Einstellungen!$B$27)/(Einstellungen!$B$28-Einstellungen!$B$27)*100))))/2/100*Einstellungen!$B$7+IF($V16="",0,$V16/100)*Einstellungen!$B$8+IF($R16="",0,MAX(0,MIN(100,(Einstellungen!$B$32-$R16)/(Einstellungen!$B$32-Einstellungen!$B$31)*100)))/100*Einstellungen!$B$9+IF($D16="",0,$D16/5*100)/100*Einstellungen!$B$10+IF($AD16="",0,$AD16)/100*Einstellungen!$B$11+IF($U16="",0,$U16/5*100)/100*Einstellungen!$B$12,0)) | AA16: =IF($X16="","",$X16*1000000000000+IF($G16="",0,$G16)*1000000+IF($H16="",0,$H16)*1000+IF($I16="",0,$I16)+IF($N16="",0,MAX(0,1000-$N16))/1000+IF($A16="",0,$A16)/1000000) | AB16: =IF($Y16="","",_xludf.RANK.EQ($Y16,$Y$2:$Y$201,0))
T17: =IFERROR(IF($Q17="","",$Q17/$H17),"") | U17: =IFERROR(IF($Q17="","",$Q17/$G17),"") | Y17: =IF(AND($L17="",$N17="",$P17=""),"",ROUND((IF($L17="",0,IF($L17<=Einstellungen!$B$16,100,IF($L17<=Einstellungen!$C$16,80+(100-80)*(Einstellungen!$C$16-$L17)/(Einstellungen!$C$16-Einstellungen!$B$16),IF($L17<=Einstellungen!$D$16,80*(Einstellungen!$D$16-$L17)/(Einstellungen!$D$16-Einstellungen!$C$16),0))))*Einstellungen!$E$16+IF($N17="",0,IF($N17<=Einstellungen!$B$17,100,IF($N17<=Einstellungen!$C$17,80+(100-80)*(Einstellungen!$C$17-$N17)/(Einstellungen!$C$17-Einstellungen!$B$17),IF($N17<=Einstellungen!$D$17,80*(Einstellungen!$D$17-$N17)/(Einstellungen!$D$17-Einstellungen!$C$17),0))))*Einstellungen!$E$17+IF($P17="",0,IF($P17<=Einstellungen!$B$18,100,IF($P17<=Einstellungen!$C$18,80+(100-80)*(Einstellungen!$C$18-$P17)/(Einstellungen!$C$18-Einstellungen!$B$18),IF($P17<=Einstellungen!$D$18,80*(Einstellungen!$D$18-$P17)/(Einstellungen!$D$18-Einstellungen!$C$18),0))))*Einstellungen!$E$18)/(Einstellungen!$E$16+Einstellungen!$E$17+Einstellungen!$E$18),0)) | Z17: =IF(AND($E17="",$D17="",$G17="",$V17="",$Q17="",$T17="",$W17="",$U17=""),"",ROUND(IF($E17="",0,IF($E17<Einstellungen!$B$21,0,IF($E17>=Einstellungen!$B$22,100,($E17-Einstellungen!$B$21)/(Einstellungen!$B$22-Einstellungen!$B$21)*100)))/100*Einstellungen!$B$5+IF($W17="",0,$W17/100)*Einstellungen!$B$6+(IF($G17="",0,MAX(0,MIN(100,($G17-Einstellungen!$B$25)/(Einstellungen!$B$26-Einstellungen!$B$25)*100)))+IF($I17="",0,MAX(0,MIN(100,($I17-Einstellungen!$B$27)/(Einstellungen!$B$28-Einstellungen!$B$27)*100))))/2/100*Einstellungen!$B$7+IF($V17="",0,$V17/100)*Einstellungen!$B$8+IF($R17="",0,MAX(0,MIN(100,(Einstellungen!$B$32-$R17)/(Einstellungen!$B$32-Einstellungen!$B$31)*100)))/100*Einstellungen!$B$9+IF($D17="",0,$D17/5*100)/100*Einstellungen!$B$10+IF($AD17="",0,$AD17)/100*Einstellungen!$B$11+IF($U17="",0,$U17/5*100)/100*Einstellungen!$B$12,0)) | AA17: =IF($X17="","",$X17*1000000000000+IF($G17="",0,$G17)*1000000+IF($H17="",0,$H17)*1000+IF($I17="",0,$I17)+IF($N17="",0,MAX(0,1000-$N17))/1000+IF($A17="",0,$A17)/1000000) | AB17: =IF($Y17="","",_xludf.RANK.EQ($Y17,$Y$2:$Y$201,0))
T18: =IFERROR(IF($Q18="","",$Q18/$H18),"") | U18: =IFERROR(IF($Q18="","",$Q18/$G18),"") | Y18: =IF(AND($L18="",$N18="",$P18=""),"",ROUND((IF($L18="",0,IF($L18<=Einstellungen!$B$16,100,IF($L18<=Einstellungen!$C$16,80+(100-80)*(Einstellungen!$C$16-$L18)/(Einstellungen!$C$16-Einstellungen!$B$16),IF($L18<=Einstellungen!$D$16,80*(Einstellungen!$D$16-$L18)/(Einstellungen!$D$16-Einstellungen!$C$16),0))))*Einstellungen!$E$16+IF($N18="",0,IF($N18<=Einstellungen!$B$17,100,IF($N18<=Einstellungen!$C$17,80+(100-80)*(Einstellungen!$C$17-$N18)/(Einstellungen!$C$17-Einstellungen!$B$17),IF($N18<=Einstellungen!$D$17,80*(Einstellungen!$D$17-$N18)/(Einstellungen!$D$17-Einstellungen!$C$17),0))))*Einstellungen!$E$17+IF($P18="",0,IF($P18<=Einstellungen!$B$18,100,IF($P18<=Einstellungen!$C$18,80+(100-80)*(Einstellungen!$C$18-$P18)/(Einstellungen!$C$18-Einstellungen!$B$18),IF($P18<=Einstellungen!$D$18,80*(Einstellungen!$D$18-$P18)/(Einstellungen!$D$18-Einstellungen!$C$18),0))))*Einstellungen!$E$18)/(Einstellungen!$E$16+Einstellungen!$E$17+Einstellungen!$E$18),0)) | Z18: =IF(AND($E18="",$D18="",$G18="",$V18="",$Q18="",$T18="",$W18="",$U18=""),"",ROUND(IF($E18="",0,IF($E18<Einstellungen!$B$21,0,IF($E18>=Einstellungen!$B$22,100,($E18-Einstellungen!$B$21)/(Einstellungen!$B$22-Einstellungen!$B$21)*100)))/100*Einstellungen!$B$5+IF($W18="",0,$W18/100)*Einstellungen!$B$6+(IF($G18="",0,MAX(0,MIN(100,($G18-Einstellungen!$B$25)/(Einstellungen!$B$26-Einstellungen!$B$25)*100)))+IF($I18="",0,MAX(0,MIN(100,($I18-Einstellungen!$B$27)/(Einstellungen!$B$28-Einstellungen!$B$27)*100))))/2/100*Einstellungen!$B$7+IF($V18="",0,$V18/100)*Einstellungen!$B$8+IF($R18="",0,MAX(0,MIN(100,(Einstellungen!$B$32-$R18)/(Einstellungen!$B$32-Einstellungen!$B$31)*100)))/100*Einstellungen!$B$9+IF($D18="",0,$D18/5*100)/100*Einstellungen!$B$10+IF($AD18="",0,$AD18)/100*Einstellungen!$B$11+IF($U18="",0,$U18/5*100)/100*Einstellungen!$B$12,0)) | AA18: =IF($X18="","",$X18*1000000000000+IF($G18="",0,$G18)*1000000+IF($H18="",0,$H18)*1000+IF($I18="",0,$I18)+IF($N18="",0,MAX(0,1000-$N18))/1000+IF($A18="",0,$A18)/1000000) | AB18: =IF($Y18="","",_xludf.RANK.EQ($Y18,$Y$2:$Y$201,0))
T19: =IFERROR(IF($Q19="","",$Q19/$H19),"") | U19: =IFERROR(IF($Q19="","",$Q19/$G19),"") | Y19: =IF(AND($L19="",$N19="",$P19=""),"",ROUND((IF($L19="",0,IF($L19<=Einstellungen!$B$16,100,IF($L19<=Einstellungen!$C$16,80+(100-80)*(Einstellungen!$C$16-$L19)/(Einstellungen!$C$16-Einstellungen!$B$16),IF($L19<=Einstellungen!$D$16,80*(Einstellungen!$D$16-$L19)/(Einstellungen!$D$16-Einstellungen!$C$16),0))))*Einstellungen!$E$16+IF($N19="",0,IF($N19<=Einstellungen!$B$17,100,IF($N19<=Einstellungen!$C$17,80+(100-80)*(Einstellungen!$C$17-$N19)/(Einstellungen!$C$17-Einstellungen!$B$17),IF($N19<=Einstellungen!$D$17,80*(Einstellungen!$D$17-$N19)/(Einstellungen!$D$17-Einstellungen!$C$17),0))))*Einstellungen!$E$17+IF($P19="",0,IF($P19<=Einstellungen!$B$18,100,IF($P19<=Einstellungen!$C$18,80+(100-80)*(Einstellungen!$C$18-$P19)/(Einstellungen!$C$18-Einstellungen!$B$18),IF($P19<=Einstellungen!$D$18,80*(Einstellungen!$D$18-$P19)/(Einstellungen!$D$18-Einstellungen!$C$18),0))))*Einstellungen!$E$18)/(Einstellungen!$E$16+Einstellungen!$E$17+Einstellungen!$E$18),0)) | Z19: =IF(AND($E19="",$D19="",$G19="",$V19="",$Q19="",$T19="",$W19="",$U19=""),"",ROUND(IF($E19="",0,IF($E19<Einstellungen!$B$21,0,IF($E19>=Einstellungen!$B$22,100,($E19-Einstellungen!$B$21)/(Einstellungen!$B$22-Einstellungen!$B$21)*100)))/100*Einstellungen!$B$5+IF($W19="",0,$W19/100)*Einstellungen!$B$6+(IF($G19="",0,MAX(0,MIN(100,($G19-Einstellungen!$B$25)/(Einstellungen!$B$26-Einstellungen!$B$25)*100)))+IF($I19="",0,MAX(0,MIN(100,($I19-Einstellungen!$B$27)/(Einstellungen!$B$28-Einstellungen!$B$27)*100))))/2/100*Einstellungen!$B$7+IF($V19="",0,$V19/100)*Einstellungen!$B$8+IF($R19="",0,MAX(0,MIN(100,(Einstellungen!$B$32-$R19)/(Einstellungen!$B$32-Einstellungen!$B$31)*100)))/100*Einstellungen!$B$9+IF($D19="",0,$D19/5*100)/100*Einstellungen!$B$10+IF($AD19="",0,$AD19)/100*Einstellungen!$B$11+IF($U19="",0,$U19/5*100)/100*Einstellungen!$B$12,0)) | AA19: =IF($X19="","",$X19*1000000000000+IF($G19="",0,$G19)*1000000+IF($H19="",0,$H19)*1000+IF($I19="",0,$I19)+IF($N19="",0,MAX(0,1000-$N19))/1000+IF($A19="",0,$A19)/1000000) | AB19: =IF($Y19="","",_xludf.RANK.EQ($Y19,$Y$2:$Y$201,0))
T20: =IFERROR(IF($Q20="","",$Q20/$H20),"") | U20: =IFERROR(IF($Q20="","",$Q20/$G20),"") | Y20: =IF(AND($L20="",$N20="",$P20=""),"",ROUND((IF($L20="",0,IF($L20<=Einstellungen!$B$16,100,IF($L20<=Einstellungen!$C$16,80+(100-80)*(Einstellungen!$C$16-$L20)/(Einstellungen!$C$16-Einstellungen!$B$16),IF($L20<=Einstellungen!$D$16,80*(Einstellungen!$D$16-$L20)/(Einstellungen!$D$16-Einstellungen!$C$16),0))))*Einstellungen!$E$16+IF($N20="",0,IF($N20<=Einstellungen!$B$17,100,IF($N20<=Einstellungen!$C$17,80+(100-80)*(Einstellungen!$C$17-$N20)/(Einstellungen!$C$17-Einstellungen!$B$17),IF($N20<=Einstellungen!$D$17,80*(Einstellungen!$D$17-$N20)/(Einstellungen!$D$17-Einstellungen!$C$17),0))))*Einstellungen!$E$17+IF($P20="",0,IF($P20<=Einstellungen!$B$18,100,IF($P20<=Einstellungen!$C$18,80+(100-80)*(Einstellungen!$C$18-$P20)/(Einstellungen!$C$18-Einstellungen!$B$18),IF($P20<=Einstellungen!$D$18,80*(Einstellungen!$D$18-$P20)/(Einstellungen!$D$18-Einstellungen!$C$18),0))))*Einstellungen!$E$18)/(Einstellungen!$E$16+Einstellungen!$E$17+Einstellungen!$E$18),0)) | Z20: =IF(AND($E20="",$D20="",$G20="",$V20="",$Q20="",$T20="",$W20="",$U20=""),"",ROUND(IF($E20="",0,IF($E20<Einstellungen!$B$21,0,IF($E20>=Einstellungen!$B$22,100,($E20-Einstellungen!$B$21)/(Einstellungen!$B$22-Einstellungen!$B$21)*100)))/100*Einstellungen!$B$5+IF($W20="",0,$W20/100)*Einstellungen!$B$6+(IF($G20="",0,MAX(0,MIN(100,($G20-Einstellungen!$B$25)/(Einstellungen!$B$26-Einstellungen!$B$25)*100)))+IF($I20="",0,MAX(0,MIN(100,($I20-Einstellungen!$B$27)/(Einstellungen!$B$28-Einstellungen!$B$27)*100))))/2/100*Einstellungen!$B$7+IF($V20="",0,$V20/100)*Einstellungen!$B$8+IF($R20="",0,MAX(0,MIN(100,(Einstellungen!$B$32-$R20)/(Einstellungen!$B$32-Einstellungen!$B$31)*100)))/100*Einstellungen!$B$9+IF($D20="",0,$D20/5*100)/100*Einstellungen!$B$10+IF($AD20="",0,$AD20)/100*Einstellungen!$B$11+IF($U20="",0,$U20/5*100)/100*Einstellungen!$B$12,0)) | AA20: =IF($X20="","",$X20*1000000000000+IF($G20="",0,$G20)*1000000+IF($H20="",0,$H20)*1000+IF($I20="",0,$I20)+IF($N20="",0,MAX(0,1000-$N20))/1000+IF($A20="",0,$A20)/1000000) | AB20: =IF($Y20="","",_xludf.RANK.EQ($Y20,$Y$2:$Y$201,0))
T21: =IFERROR(IF($Q21="","",$Q21/$H21),"") | U21: =IFERROR(IF($Q21="","",$Q21/$G21),"") | Y21: =IF(AND($L21="",$N21="",$P21=""),"",ROUND((IF($L21="",0,IF($L21<=Einstellungen!$B$16,100,IF($L21<=Einstellungen!$C$16,80+(100-80)*(Einstellungen!$C$16-$L21)/(Einstellungen!$C$16-Einstellungen!$B$16),IF($L21<=Einstellungen!$D$16,80*(Einstellungen!$D$16-$L21)/(Einstellungen!$D$16-Einstellungen!$C$16),0))))*Einstellungen!$E$16+IF($N21="",0,IF($N21<=Einstellungen!$B$17,100,IF($N21<=Einstellungen!$C$17,80+(100-80)*(Einstellungen!$C$17-$N21)/(Einstellungen!$C$17-Einstellungen!$B$17),IF($N21<=Einstellungen!$D$17,80*(Einstellungen!$D$17-$N21)/(Einstellungen!$D$17-Einstellungen!$C$17),0))))*Einstellungen!$E$17+IF($P21="",0,IF($P21<=Einstellungen!$B$18,100,IF($P21<=Einstellungen!$C$18,80+(100-80)*(Einstellungen!$C$18-$P21)/(Einstellungen!$C$18-Einstellungen!$B$18),IF($P21<=Einstellungen!$D$18,80*(Einstellungen!$D$18-$P21)/(Einstellungen!$D$18-Einstellungen!$C$18),0))))*Einstellungen!$E$18)/(Einstellungen!$E$16+Einstellungen!$E$17+Einstellungen!$E$18),0)) | Z21: =IF(AND($E21="",$D21="",$G21="",$V21="",$Q21="",$T21="",$W21="",$U21=""),"",ROUND(IF($E21="",0,IF($E21<Einstellungen!$B$21,0,IF($E21>=Einstellungen!$B$22,100,($E21-Einstellungen!$B$21)/(Einstellungen!$B$22-Einstellungen!$B$21)*100)))/100*Einstellungen!$B$5+IF($W21="",0,$W21/100)*Einstellungen!$B$6+(IF($G21="",0,MAX(0,MIN(100,($G21-Einstellungen!$B$25)/(Einstellungen!$B$26-Einstellungen!$B$25)*100)))+IF($I21="",0,MAX(0,MIN(100,($I21-Einstellungen!$B$27)/(Einstellungen!$B$28-Einstellungen!$B$27)*100))))/2/100*Einstellungen!$B$7+IF($V21="",0,$V21/100)*Einstellungen!$B$8+IF($R21="",0,MAX(0,MIN(100,(Einstellungen!$B$32-$R21)/(Einstellungen!$B$32-Einstellungen!$B$31)*100)))/100*Einstellungen!$B$9+IF($D21="",0,$D21/5*100)/100*Einstellungen!$B$10+IF($AD21="",0,$AD21)/100*Einstellungen!$B$11+IF($U21="",0,$U21/5*100)/100*Einstellungen!$B$12,0)) | AA21: =IF($X21="","",$X21*1000000000000+IF($G21="",0,$G21)*1000000+IF($H21="",0,$H21)*1000+IF($I21="",0,$I21)+IF($N21="",0,MAX(0,1000-$N21))/1000+IF($A21="",0,$A21)/1000000) | AB21: =IF($Y21="","",_xludf.RANK.EQ($Y21,$Y$2:$Y$201,0))
T22: =IFERROR(IF($Q22="","",$Q22/$H22),"") | U22: =IFERROR(IF($Q22="","",$Q22/$G22),"") | Y22: =IF(AND($L22="",$N22="",$P22=""),"",ROUND((IF($L22="",0,IF($L22<=Einstellungen!$B$16,100,IF($L22<=Einstellungen!$C$16,80+(100-80)*(Einstellungen!$C$16-$L22)/(Einstellungen!$C$16-Einstellungen!$B$16),IF($L22<=Einstellungen!$D$16,80*(Einstellungen!$D$16-$L22)/(Einstellungen!$D$16-Einstellungen!$C$16),0))))*Einstellungen!$E$16+IF($N22="",0,IF($N22<=Einstellungen!$B$17,100,IF($N22<=Einstellungen!$C$17,80+(100-80)*(Einstellungen!$C$17-$N22)/(Einstellungen!$C$17-Einstellungen!$B$17),IF($N22<=Einstellungen!$D$17,80*(Einstellungen!$D$17-$N22)/(Einstellungen!$D$17-Einstellungen!$C$17),0))))*Einstellungen!$E$17+IF($P22="",0,IF($P22<=Einstellungen!$B$18,100,IF($P22<=Einstellungen!$C$18,80+(100-80)*(Einstellungen!$C$18-$P22)/(Einstellungen!$C$18-Einstellungen!$B$18),IF($P22<=Einstellungen!$D$18,80*(Einstellungen!$D$18-$P22)/(Einstellungen!$D$18-Einstellungen!$C$18),0))))*Einstellungen!$E$18)/(Einstellungen!$E$16+Einstellungen!$E$17+Einstellungen!$E$18),0)) | Z22: =IF(AND($E22="",$D22="",$G22="",$V22="",$Q22="",$T22="",$W22="",$U22=""),"",ROUND(IF($E22="",0,IF($E22<Einstellungen!$B$21,0,IF($E22>=Einstellungen!$B$22,100,($E22-Einstellungen!$B$21)/(Einstellungen!$B$22-Einstellungen!$B$21)*100)))/100*Einstellungen!$B$5+IF($W22="",0,$W22/100)*Einstellungen!$B$6+(IF($G22="",0,MAX(0,MIN(100,($G22-Einstellungen!$B$25)/(Einstellungen!$B$26-Einstellungen!$B$25)*100)))+IF($I22="",0,MAX(0,MIN(100,($I22-Einstellungen!$B$27)/(Einstellungen!$B$28-Einstellungen!$B$27)*100))))/2/100*Einstellungen!$B$7+IF($V22="",0,$V22/100)*Einstellungen!$B$8+IF($R22="",0,MAX(0,MIN(100,(Einstellungen!$B$32-$R22)/(Einstellungen!$B$32-Einstellungen!$B$31)*100)))/100*Einstellungen!$B$9+IF($D22="",0,$D22/5*100)/100*Einstellungen!$B$10+IF($AD22="",0,$AD22)/100*Einstellungen!$B$11+IF($U22="",0,$U22/5*100)/100*Einstellungen!$B$12,0)) | AA22: =IF($X22="","",$X22*1000000000000+IF($G22="",0,$G22)*1000000+IF($H22="",0,$H22)*1000+IF($I22="",0,$I22)+IF($N22="",0,MAX(0,1000-$N22))/1000+IF($A22="",0,$A22)/1000000) | AB22: =IF($Y22="","",_xludf.RANK.EQ($Y22,$Y$2:$Y$201,0))
T23: =IFERROR(IF($Q23="","",$Q23/$H23),"") | U23: =IFERROR(IF($Q23="","",$Q23/$G23),"") | Y23: =IF(AND($L23="",$N23="",$P23=""),"",ROUND((IF($L23="",0,IF($L23<=Einstellungen!$B$16,100,IF($L23<=Einstellungen!$C$16,80+(100-80)*(Einstellungen!$C$16-$L23)/(Einstellungen!$C$16-Einstellungen!$B$16),IF($L23<=Einstellungen!$D$16,80*(Einstellungen!$D$16-$L23)/(Einstellungen!$D$16-Einstellungen!$C$16),0))))*Einstellungen!$E$16+IF($N23="",0,IF($N23<=Einstellungen!$B$17,100,IF($N23<=Einstellungen!$C$17,80+(100-80)*(Einstellungen!$C$17-$N23)/(Einstellungen!$C$17-Einstellungen!$B$17),IF($N23<=Einstellungen!$D$17,80*(Einstellungen!$D$17-$N23)/(Einstellungen!$D$17-Einstellungen!$C$17),0))))*Einstellungen!$E$17+IF($P23="",0,IF($P23<=Einstellungen!$B$18,100,IF($P23<=Einstellungen!$C$18,80+(100-80)*(Einstellungen!$C$18-$P23)/(Einstellungen!$C$18-Einstellungen!$B$18),IF($P23<=Einstellungen!$D$18,80*(Einstellungen!$D$18-$P23)/(Einstellungen!$D$18-Einstellungen!$C$18),0))))*Einstellungen!$E$18)/(Einstellungen!$E$16+Einstellungen!$E$17+Einstellungen!$E$18),0)) | Z23: =IF(AND($E23="",$D23="",$G23="",$V23="",$Q23="",$T23="",$W23="",$U23=""),"",ROUND(IF($E23="",0,IF($E23<Einstellungen!$B$21,0,IF($E23>=Einstellungen!$B$22,100,($E23-Einstellungen!$B$21)/(Einstellungen!$B$22-Einstellungen!$B$21)*100)))/100*Einstellungen!$B$5+IF($W23="",0,$W23/100)*Einstellungen!$B$6+(IF($G23="",0,MAX(0,MIN(100,($G23-Einstellungen!$B$25)/(Einstellungen!$B$26-Einstellungen!$B$25)*100)))+IF($I23="",0,MAX(0,MIN(100,($I23-Einstellungen!$B$27)/(Einstellungen!$B$28-Einstellungen!$B$27)*100))))/2/100*Einstellungen!$B$7+IF($V23="",0,$V23/100)*Einstellungen!$B$8+IF($R23="",0,MAX(0,MIN(100,(Einstellungen!$B$32-$R23)/(Einstellungen!$B$32-Einstellungen!$B$31)*100)))/100*Einstellungen!$B$9+IF($D23="",0,$D23/5*100)/100*Einstellungen!$B$10+IF($AD23="",0,$AD23)/100*Einstellungen!$B$11+IF($U23="",0,$U23/5*100)/100*Einstellungen!$B$12,0)) | AA23: =IF($X23="","",$X23*1000000000000+IF($G23="",0,$G23)*1000000+IF($H23="",0,$H23)*1000+IF($I23="",0,$I23)+IF($N23="",0,MAX(0,1000-$N23))/1000+IF($A23="",0,$A23)/1000000) | AB23: =IF($Y23="","",_xludf.RANK.EQ($Y23,$Y$2:$Y$201,0))
T24: =IFERROR(IF($Q24="","",$Q24/$H24),"") | U24: =IFERROR(IF($Q24="","",$Q24/$G24),"") | Y24: =IF(AND($L24="",$N24="",$P24=""),"",ROUND((IF($L24="",0,IF($L24<=Einstellungen!$B$16,100,IF($L24<=Einstellungen!$C$16,80+(100-80)*(Einstellungen!$C$16-$L24)/(Einstellungen!$C$16-Einstellungen!$B$16),IF($L24<=Einstellungen!$D$16,80*(Einstellungen!$D$16-$L24)/(Einstellungen!$D$16-Einstellungen!$C$16),0))))*Einstellungen!$E$16+IF($N24="",0,IF($N24<=Einstellungen!$B$17,100,IF($N24<=Einstellungen!$C$17,80+(100-80)*(Einstellungen!$C$17-$N24)/(Einstellungen!$C$17-Einstellungen!$B$17),IF($N24<=Einstellungen!$D$17,80*(Einstellungen!$D$17-$N24)/(Einstellungen!$D$17-Einstellungen!$C$17),0))))*Einstellungen!$E$17+IF($P24="",0,IF($P24<=Einstellungen!$B$18,100,IF($P24<=Einstellungen!$C$18,80+(100-80)*(Einstellungen!$C$18-$P24)/(Einstellungen!$C$18-Einstellungen!$B$18),IF($P24<=Einstellungen!$D$18,80*(Einstellungen!$D$18-$P24)/(Einstellungen!$D$18-Einstellungen!$C$18),0))))*Einstellungen!$E$18)/(Einstellungen!$E$16+Einstellungen!$E$17+Einstellungen!$E$18),0)) | Z24: =IF(AND($E24="",$D24="",$G24="",$V24="",$Q24="",$T24="",$W24="",$U24=""),"",ROUND(IF($E24="",0,IF($E24<Einstellungen!$B$21,0,IF($E24>=Einstellungen!$B$22,100,($E24-Einstellungen!$B$21)/(Einstellungen!$B$22-Einstellungen!$B$21)*100)))/100*Einstellungen!$B$5+IF($W24="",0,$W24/100)*Einstellungen!$B$6+(IF($G24="",0,MAX(0,MIN(100,($G24-Einstellungen!$B$25)/(Einstellungen!$B$26-Einstellungen!$B$25)*100)))+IF($I24="",0,MAX(0,MIN(100,($I24-Einstellungen!$B$27)/(Einstellungen!$B$28-Einstellungen!$B$27)*100))))/2/100*Einstellungen!$B$7+IF($V24="",0,$V24/100)*Einstellungen!$B$8+IF($R24="",0,MAX(0,MIN(100,(Einstellungen!$B$32-$R24)/(Einstellungen!$B$32-Einstellungen!$B$31)*100)))/100*Einstellungen!$B$9+IF($D24="",0,$D24/5*100)/100*Einstellungen!$B$10+IF($AD24="",0,$AD24)/100*Einstellungen!$B$11+IF($U24="",0,$U24/5*100)/100*Einstellungen!$B$12,0)) | AA24: =IF($X24="","",$X24*1000000000000+IF($G24="",0,$G24)*1000000+IF($H24="",0,$H24)*1000+IF($I24="",0,$I24)+IF($N24="",0,MAX(0,1000-$N24))/1000+IF($A24="",0,$A24)/1000000) | AB24: =IF($Y24="","",_xludf.RANK.EQ($Y24,$Y$2:$Y$201,0))
T25: =IFERROR(IF($Q25="","",$Q25/$H25),"") | U25: =IFERROR(IF($Q25="","",$Q25/$G25),"") | Y25: =IF(AND($L25="",$N25="",$P25=""),"",ROUND((IF($L25="",0,IF($L25<=Einstellungen!$B$16,100,IF($L25<=Einstellungen!$C$16,80+(100-80)*(Einstellungen!$C$16-$L25)/(Einstellungen!$C$16-Einstellungen!$B$16),IF($L25<=Einstellungen!$D$16,80*(Einstellungen!$D$16-$L25)/(Einstellungen!$D$16-Einstellungen!$C$16),0))))*Einstellungen!$E$16+IF($N25="",0,IF($N25<=Einstellungen!$B$17,100,IF($N25<=Einstellungen!$C$17,80+(100-80)*(Einstellungen!$C$17-$N25)/(Einstellungen!$C$17-Einstellungen!$B$17),IF($N25<=Einstellungen!$D$17,80*(Einstellungen!$D$17-$N25)/(Einstellungen!$D$17-Einstellungen!$C$17),0))))*Einstellungen!$E$17+IF($P25="",0,IF($P25<=Einstellungen!$B$18,100,IF($P25<=Einstellungen!$C$18,80+(100-80)*(Einstellungen!$C$18-$P25)/(Einstellungen!$C$18-Einstellungen!$B$18),IF($P25<=Einstellungen!$D$18,80*(Einstellungen!$D$18-$P25)/(Einstellungen!$D$18-Einstellungen!$C$18),0))))*Einstellungen!$E$18)/(Einstellungen!$E$16+Einstellungen!$E$17+Einstellungen!$E$18),0)) | Z25: =IF(AND($E25="",$D25="",$G25="",$V25="",$Q25="",$T25="",$W25="",$U25=""),"",ROUND(IF($E25="",0,IF($E25<Einstellungen!$B$21,0,IF($E25>=Einstellungen!$B$22,100,($E25-Einstellungen!$B$21)/(Einstellungen!$B$22-Einstellungen!$B$21)*100)))/100*Einstellungen!$B$5+IF($W25="",0,$W25/100)*Einstellungen!$B$6+(IF($G25="",0,MAX(0,MIN(100,($G25-Einstellungen!$B$25)/(Einstellungen!$B$26-Einstellungen!$B$25)*100)))+IF($I25="",0,MAX(0,MIN(100,($I25-Einstellungen!$B$27)/(Einstellungen!$B$28-Einstellungen!$B$27)*100))))/2/100*Einstellungen!$B$7+IF($V25="",0,$V25/100)*Einstellungen!$B$8+IF($R25="",0,MAX(0,MIN(100,(Einstellungen!$B$32-$R25)/(Einstellungen!$B$32-Einstellungen!$B$31)*100)))/100*Einstellungen!$B$9+IF($D25="",0,$D25/5*100)/100*Einstellungen!$B$10+IF($AD25="",0,$AD25)/100*Einstellungen!$B$11+IF($U25="",0,$U25/5*100)/100*Einstellungen!$B$12,0)) | AA25: =IF($X25="","",$X25*1000000000000+IF($G25="",0,$G25)*1000000+IF($H25="",0,$H25)*1000+IF($I25="",0,$I25)+IF($N25="",0,MAX(0,1000-$N25))/1000+IF($A25="",0,$A25)/1000000) | AB25: =IF($Y25="","",_xludf.RANK.EQ($Y25,$Y$2:$Y$201,0))
T26: =IFERROR(IF($Q26="","",$Q26/$H26),"") | U26: =IFERROR(IF($Q26="","",$Q26/$G26),"") | Y26: =IF(AND($L26="",$N26="",$P26=""),"",ROUND((IF($L26="",0,IF($L26<=Einstellungen!$B$16,100,IF($L26<=Einstellungen!$C$16,80+(100-80)*(Einstellungen!$C$16-$L26)/(Einstellungen!$C$16-Einstellungen!$B$16),IF($L26<=Einstellungen!$D$16,80*(Einstellungen!$D$16-$L26)/(Einstellungen!$D$16-Einstellungen!$C$16),0))))*Einstellungen!$E$16+IF($N26="",0,IF($N26<=Einstellungen!$B$17,100,IF($N26<=Einstellungen!$C$17,80+(100-80)*(Einstellungen!$C$17-$N26)/(Einstellungen!$C$17-Einstellungen!$B$17),IF($N26<=Einstellungen!$D$17,80*(Einstellungen!$D$17-$N26)/(Einstellungen!$D$17-Einstellungen!$C$17),0))))*Einstellungen!$E$17+IF($P26="",0,IF($P26<=Einstellungen!$B$18,100,IF($P26<=Einstellungen!$C$18,80+(100-80)*(Einstellungen!$C$18-$P26)/(Einstellungen!$C$18-Einstellungen!$B$18),IF($P26<=Einstellungen!$D$18,80*(Einstellungen!$D$18-$P26)/(Einstellungen!$D$18-Einstellungen!$C$18),0))))*Einstellungen!$E$18)/(Einstellungen!$E$16+Einstellungen!$E$17+Einstellungen!$E$18),0)) | Z26: =IF(AND($E26="",$D26="",$G26="",$V26="",$Q26="",$T26="",$W26="",$U26=""),"",ROUND(IF($E26="",0,IF($E26<Einstellungen!$B$21,0,IF($E26>=Einstellungen!$B$22,100,($E26-Einstellungen!$B$21)/(Einstellungen!$B$22-Einstellungen!$B$21)*100)))/100*Einstellungen!$B$5+IF($W26="",0,$W26/100)*Einstellungen!$B$6+(IF($G26="",0,MAX(0,MIN(100,($G26-Einstellungen!$B$25)/(Einstellungen!$B$26-Einstellungen!$B$25)*100)))+IF($I26="",0,MAX(0,MIN(100,($I26-Einstellungen!$B$27)/(Einstellungen!$B$28-Einstellungen!$B$27)*100))))/2/100*Einstellungen!$B$7+IF($V26="",0,$V26/100)*Einstellungen!$B$8+IF($R26="",0,MAX(0,MIN(100,(Einstellungen!$B$32-$R26)/(Einstellungen!$B$32-Einstellungen!$B$31)*100)))/100*Einstellungen!$B$9+IF($D26="",0,$D26/5*100)/100*Einstellungen!$B$10+IF($AD26="",0,$AD26)/100*Einstellungen!$B$11+IF($U26="",0,$U26/5*100)/100*Einstellungen!$B$12,0)) | AA26: =IF($X26="","",$X26*1000000000000+IF($G26="",0,$G26)*1000000+IF($H26="",0,$H26)*1000+IF($I26="",0,$I26)+IF($N26="",0,MAX(0,1000-$N26))/1000+IF($A26="",0,$A26)/1000000) | AB26: =IF($Y26="","",_xludf.RANK.EQ($Y26,$Y$2:$Y$201,0))
T27: =IFERROR(IF($Q27="","",$Q27/$H27),"") | U27: =IFERROR(IF($Q27="","",$Q27/$G27),"") | Y27: =IF(AND($L27="",$N27="",$P27=""),"",ROUND((IF($L27="",0,IF($L27<=Einstellungen!$B$16,100,IF($L27<=Einstellungen!$C$16,80+(100-80)*(Einstellungen!$C$16-$L27)/(Einstellungen!$C$16-Einstellungen!$B$16),IF($L27<=Einstellungen!$D$16,80*(Einstellungen!$D$16-$L27)/(Einstellungen!$D$16-Einstellungen!$C$16),0))))*Einstellungen!$E$16+IF($N27="",0,IF($N27<=Einstellungen!$B$17,100,IF($N27<=Einstellungen!$C$17,80+(100-80)*(Einstellungen!$C$17-$N27)/(Einstellungen!$C$17-Einstellungen!$B$17),IF($N27<=Einstellungen!$D$17,80*(Einstellungen!$D$17-$N27)/(Einstellungen!$D$17-Einstellungen!$C$17),0))))*Einstellungen!$E$17+IF($P27="",0,IF($P27<=Einstellungen!$B$18,100,IF($P27<=Einstellungen!$C$18,80+(100-80)*(Einstellungen!$C$18-$P27)/(Einstellungen!$C$18-Einstellungen!$B$18),IF($P27<=Einstellungen!$D$18,80*(Einstellungen!$D$18-$P27)/(Einstellungen!$D$18-Einstellungen!$C$18),0))))*Einstellungen!$E$18)/(Einstellungen!$E$16+Einstellungen!$E$17+Einstellungen!$E$18),0)) | Z27: =IF(AND($E27="",$D27="",$G27="",$V27="",$Q27="",$T27="",$W27="",$U27=""),"",ROUND(IF($E27="",0,IF($E27<Einstellungen!$B$21,0,IF($E27>=Einstellungen!$B$22,100,($E27-Einstellungen!$B$21)/(Einstellungen!$B$22-Einstellungen!$B$21)*100)))/100*Einstellungen!$B$5+IF($W27="",0,$W27/100)*Einstellungen!$B$6+(IF($G27="",0,MAX(0,MIN(100,($G27-Einstellungen!$B$25)/(Einstellungen!$B$26-Einstellungen!$B$25)*100)))+IF($I27="",0,MAX(0,MIN(100,($I27-Einstellungen!$B$27)/(Einstellungen!$B$28-Einstellungen!$B$27)*100))))/2/100*Einstellungen!$B$7+IF($V27="",0,$V27/100)*Einstellungen!$B$8+IF($R27="",0,MAX(0,MIN(100,(Einstellungen!$B$32-$R27)/(Einstellungen!$B$32-Einstellungen!$B$31)*100)))/100*Einstellungen!$B$9+IF($D27="",0,$D27/5*100)/100*Einstellungen!$B$10+IF($AD27="",0,$AD27)/100*Einstellungen!$B$11+IF($U27="",0,$U27/5*100)/100*Einstellungen!$B$12,0)) | AA27: =IF($X27="","",$X27*1000000000000+IF($G27="",0,$G27)*1000000+IF($H27="",0,$H27)*1000+IF($I27="",0,$I27)+IF($N27="",0,MAX(0,1000-$N27))/1000+IF($A27="",0,$A27)/1000000) | AB27: =IF($Y27="","",_xludf.RANK.EQ($Y27,$Y$2:$Y$201,0))
... T201: =IFERROR(IF($Q201="","",$Q201/$H201),"") | U201: =IFERROR(IF($Q201="","",$Q201/$G201),"") | Y201: =IF(AND($L201="",$N201="",$P201=""),"",ROUND((IF($L201="",0,IF($L201<=Einstellungen!$B$16,100,IF($L201<=Einstellungen!$C$16,80+(100-80)*(Einstellungen!$C$16-$L201)/(Einstellungen!$C$16-Einstellungen!$B$16),IF($L201<=Einstellungen!$D$16,80*(Einstellungen!$D$16-$L201)/(Einstellungen!$D$16-Einstellungen!$C$16),0))))*Einstellungen!$E$16+IF($N201="",0,IF($N201<=Einstellungen!$B$17,100,IF($N201<=Einstellungen!$C$17,80+(100-80)*(Einstellungen!$C$17-$N201)/(Einstellungen!$C$17-Einstellungen!$B$17),IF($N201<=Einstellungen!$D$17,80*(Einstellungen!$D$17-$N201)/(Einstellungen!$D$17-Einstellungen!$C$17),0))))*Einstellungen!$E$17+IF($P201="",0,IF($P201<=Einstellungen!$B$18,100,IF($P201<=Einstellungen!$C$18,80+(100-80)*(Einstellungen!$C$18-$P201)/(Einstellungen!$C$18-Einstellungen!$B$18),IF($P201<=Einstellungen!$D$18,80*(Einstellungen!$D$18-$P201)/(Einstellungen!$D$18-Einstellungen!$C$18),0))))*Einstellungen!$E$18)/(Einstellungen!$E$16+Einstellungen!$E$17+Einstellungen!$E$18),0)) | Z201: =IF(AND($E201="",$D201="",$G201="",$V201="",$Q201="",$T201="",$W201="",$U201=""),"",ROUND(IF($E201="",0,IF($E201<Einstellungen!$B$21,0,IF($E201>=Einstellungen!$B$22,100,($E201-Einstellungen!$B$21)/(Einstellungen!$B$22-Einstellungen!$B$21)*100)))/100*Einstellungen!$B$5+IF($W201="",0,$W201/100)*Einstellungen!$B$6+(IF($G201="",0,MAX(0,MIN(100,($G201-Einstellungen!$B$25)/(Einstellungen!$B$26-Einstellungen!$B$25)*100)))+IF($I201="",0,MAX(0,MIN(100,($I201-Einstellungen!$B$27)/(Einstellungen!$B$28-Einstellungen!$B$27)*100))))/2/100*Einstellungen!$B$7+IF($V201="",0,$V201/100)*Einstellungen!$B$8+IF($R201="",0,MAX(0,MIN(100,(Einstellungen!$B$32-$R201)/(Einstellungen!$B$32-Einstellungen!$B$31)*100)))/100*Einstellungen!$B$9+IF($D201="",0,$D201/5*100)/100*Einstellungen!$B$10+IF($AD201="",0,$AD201)/100*Einstellungen!$B$11+IF($U201="",0,$U201/5*100)/100*Einstellungen!$B$12,0)) | AA201: =IF($X201="","",$X201*1000000000000+IF($G201="",0,$G201)*1000000+IF($H201="",0,$H201)*1000+IF($I201="",0,$I201)+IF($N201="",0,MAX(0,1000-$N201))/1000+IF($A201="",0,$A201)/1000000) | AB201: =IF($Y201="","",_xludf.RANK.EQ($Y201,$Y$2:$Y$201,0))
A202: 15 | B202: Apartment in Portals Nous, Mallorca | C202: https://www.kyero.com/en/property/17828907-apartment-for-sale-portals-nous?prime_boost_id=17828907 | E202: 3 | J202: Portals Nous | K202: 23.8 | L202: 23 | M202: 66.6 | N202: 56 | O202: 21.8 | P202: 22 | Q202: 64.3 | R202: 52 | S202: 3500000 | AH202: Quelle: Kyero
A203: 16 | B203: Country house in Felanitx, Mallorca | C203: https://www.kyero.com/en/property/18737859-country-house-for-sale-felanitx?prime_boost_id=18737859 | E203: 4 | G203: 23160 | J203: Felanitx | K203: 45 | L203: 40 | M203: 26.8 | N203: 30 | O203: 83.2 | P203: 68 | Q203: 24.5 | R203: 26 | S203: 2435000 | U203: 105 | AH203: Quelle: Kyero
A204: 17 | B204: Villa in Santa Ponsa, Mallorca | C204: https://www.kyero.com/en/property/19926319-villa-for-sale-santa-ponsa?prime_boost_id=19926319 | E204: 4 | G204: 1448 | J204: Santa Ponsa | K204: 31.1 | L204: 28 | M204: 73.9 | N204: 61 | O204: 15.2 | P204: 19 | Q204: 71.6 | R204: 57 | S204: 3900000 | U204: 2693 | AH204: Quelle: Kyero
A205: 18 | B205: Country house in Colonia De Sant Pere, Mallorca | C205: https://www.kyero.com/en/property/19956683-country-house-for-sale-colonia-de-sant-pere | E205: 6 | G205: 14200 | J205: Mallorca | K205: 47.4 | L205: 40 | M205: 51.8 | N205: 55 | O205: 70 | P205: 56 | Q205: 49.5 | R205: 51 | S205: 2350000 | U205: 165 | AH205: Quelle: Kyero
A206: 19 | B206: Villa in Bendinat, Mallorca | C206: https://www.kyero.com/en/property/18538834-villa-for-sale-bendinat | E206: 4 | G206: 753 | J206: Bendinat | K206: 23.1 | L206: 22 | M206: 65.8 | N206: 55 | O206: 23.2 | P206: 23 | Q206: 63.5 | R206: 51 | S206: 3100000 | U206: 4117 | AH206: Quelle: Kyero
A207: 20 | B207: Villa in Cala Murada, Mallorca | C207: https://www.kyero.com/en/property/18605783-villa-for-sale-cala-murada | E207: 6 | G207: 1650 | J207: Mallorca | K207: 47.4 | L207: 40 | M207: 51.8 | N207: 55 | O207: 70 | P207: 56 | Q207: 49.5 | R207: 51 | S207: 2790000 | U207: 1691 | AH207: Quelle: Kyero
A208: 21 | B208: Country house in Santa Maria Del Cami, Mallorca | C208: https://www.kyero.com/en/property/20534135-country-house-for-sale-santa-maria-del-cami | E208: 7 | G208: 13500 | J208: Mallorca | K208: 47.4 | L208: 40 | M208: 51.8 | N208: 55 | O208: 70 | P208: 56 | Q208: 49.5 | R208: 51 | S208: 3000000 | U208: 222 | AH208: Quelle: Kyero
A209: 22 | B209: Country house in Llubi, Mallorca | C209: https://www.kyero.com/en/property/20467885-country-house-for-sale-llubi | E209: 4 | G209: 15000 | J209: Mallorca | K209: 47.4 | L209: 40 | M209: 51.8 | N209: 55 | O209: 70 | P209: 56 | Q209: 49.5 | R209: 51 | S209: 2750000 | U209: 183 | AH209: Quelle: Kyero
A210: 23 | B210: Finca in Campos, Mallorca | C210: https://www.kyero.com/en/property/20520519-country-house-for-sale-campos | E210: 6 | G210: 14200 | J210: Mallorca | K210: 47.4 | L210: 40 | M210: 51.8 | N210: 55 | O210: 70 | P210: 56 | Q210: 49.5 | R210: 51 | S210: 3650000 | U210: 257 | AH210: Quelle: Kyero
A211: 24 | B211: Country house in Sant Llorenc Des Cardassar, Mallorca | C211: https://www.kyero.com/en/property/20510970-country-house-for-sale-sant-llorenc-des-cardassar | E211: 4 | G211: 17545 | J211: Mallorca | K211: 47.4 | L211: 40 | M211: 51.8 | N211: 55 | O211: 70 | P211: 56 | Q211: 49.5 | R211: 51 | S211: 2690000 | U211: 153 | AH211: Quelle: Kyero
A212: 25 | B212: Remote viewing available | C212: https://www.kyero.com/en/property/20539651-apartment-for-sale-palma-de-mallorca | E212: 3 | J212: Palma | K212: 9.7 | L212: 14 | M212: 52.5 | N212: 47 | O212: 32.1 | P212: 36 | Q212: 50.2 | R212: 44 | S212: 3250000 | AH212: Quelle: Kyero
A213: 26 | B213: Country house in Binissalem, Mallorca | C213: https://www.kyero.com/en/property/20533859-country-house-for-sale-binissalem | E213: 8 | G213: 15000 | J213: Mallorca | K213: 47.4 | L213: 40 | M213: 51.8 | N213: 55 | O213: 70 | P213: 56 | Q213: 49.5 | R213: 51 | S213: 3400000 | U213: 227 | AH213: Quelle: Kyero
...

Sheet Einstellungen
A1: Bewertungssystem Einstellungen (blau = anpassbar)
A4: GEWICHTE (Summe = 100)
A5: Zimmer & Platz | B5: 20
A6: Erreichbarkeit (Flughafen/Daia/Andratx/Ses Salines) | B6: 10
A7: Grundstück & Garten | B7: 15
A8: Vermietlizenz | B8: 10
A9: Preis/Budget | B9: 15
A10: Charme / Ästhetik (1-5, manuell) | B10: 10
A11: Renovierung (0-100) | B11: 0
A12: Bewirtschaftung (1-5, 5=pflegeleicht) | B12: 5
A13: Preis-Leistung (€/m²) | B13: 15
A14: Summe | B14: =SUM(B5:B13)
A16: ERREICHBARKEIT (Minuten) | B16: Ideal | C16: Akzeptabel | D16: Dealbreaker | E16: Gewicht intern
A17: Flughafen | B17: 20 | C17: 35 | D17: 50 | E17: 25
A18: Daia (Hotel Corazón) | B18: 20 | C18: 40 | D18: 70 | E18: 40
A19: Andratx | B19: 30 | C19: 45 | D19: 60 | E19: 15
A20: Ses Salines | B20: 15 | C20: 30 | D20: 45 | E20: 20
A22: ZIMMER
A23: Minimum Zimmer | B23: 5
A24: Ideal Zimmer | B24: 8
A26: GRUNDSTÜCK & GARTEN
A27: Min Grundstück (m²) | B27: 3000
A28: Ideal Grundstück (m²) | B28: 15000
A29: Min Garten/Rasen (m²) | B29: 1000
A30: Ideal Garten/Rasen (m²) | B30: 5000
A32: VALUE
A33: Ziel €/m² (bebaut) | B33: 5000
A34: Max €/m² (bebaut) | B34: 12000

Sheet Rangliste
A1: Rangliste (automatisch aus 'Objekte')
A3: Rang | B3: Name | C3: Score | D3: Erreichb. | E3: Flugh.(min) | F3: Daia (min) | G3: Andratx (min) | H3: Zimmer | I3: Grundstück | J3: Garten | K3: Preis (€) | L3: Lizenz | M3: Charme | N3: Bewirtsch. | O3: Kommentar | P3: URL | Q3: Reno-Score | R3: Baujahr
A4: 1 | B4: =IFERROR(INDEX(Objekte!$B$2:$B$201,MATCH($A4,Objekte!$Z$2:$Z$201,0)),"") | C4: =IFERROR(INDEX(Objekte!$X$2:$X$201,MATCH($A4,Objekte!$Z$2:$Z$201,0)),"") | D4: =IFERROR(INDEX(Objekte!$W$2:$W$201,MATCH($A4,Objekte!$Z$2:$Z$201,0)),"") | E4: =IFERROR(INDEX(Objekte!$L$2:$L$201,MATCH($A4,Objekte!$Z$2:$Z$201,0)),"") | F4: =IFERROR(INDEX(Objekte!$N$2:$N$201,MATCH($A4,Objekte!$Z$2:$Z$201,0)),"") | G4: =IFERROR(INDEX(Objekte!$P$2:$P$201,MATCH($A4,Objekte!$Z$2:$Z$201,0)),"") | H4: =IFERROR(INDEX(Objekte!$E$2:$E$201,MATCH($A4,Objekte!$Z$2:$Z$201,0)),"") | I4: =IFERROR(INDEX(Objekte!$G$2:$G$201,MATCH($A4,Objekte!$Z$2:$Z$201,0)),"") | J4: =IFERROR(INDEX(Objekte!$I$2:$I$201,MATCH($A4,Objekte!$Z$2:$Z$201,0)),"") | K4: =IFERROR(INDEX(Objekte!$Q$2:$Q$201,MATCH($A4,Objekte!$Z$2:$Z$201,0)),"") | L4: =IFERROR(INDEX(Objekte!$V$2:$V$201,MATCH($A4,Objekte!$Z$2:$Z$201,0)),"") | M4: =IFERROR(INDEX(Objekte!$D$2:$D$201,MATCH($A4,Objekte!$Z$2:$Z$201,0)),"") | N4: =IFERROR(INDEX(Objekte!$U$2:$U$201,MATCH($A4,Objekte!$Z$2:$Z$201,0)),"") | O4: =IFERROR(INDEX(Objekte!$AF$2:$AF$201,MATCH($A4,Objekte!$Z$2:$Z$201,0)),"") | P4: =IFERROR(INDEX(Objekte!$C$2:$C$201,MATCH($A4,Objekte!$Z$2:$Z$201,0)),"") | Q4: =IFERROR(INDEX(Objekte!$AD$2:$AD$201,MATCH($A4,Objekte!$Z$2:$Z$201,0)),"") | R4: =IFERROR(INDEX(Objekte!$AB$2:$AB$201,MATCH($A4,Objekte!$Z$2:$Z$201,0)),"")
A5: 2 | B5: =IFERROR(INDEX(Objekte!$B$2:$B$201,MATCH($A5,Objekte!$Z$2:$Z$201,0)),"") | C5: =IFERROR(INDEX(Objekte!$X$2:$X$201,MATCH($A5,Objekte!$Z$2:$Z$201,0)),"") | D5: =IFERROR(INDEX(Objekte!$W$2:$W$201,MATCH($A5,Objekte!$Z$2:$Z$201,0)),"") | E5: =IFERROR(INDEX(Objekte!$L$2:$L$201,MATCH($A5,Objekte!$Z$2:$Z$201,0)),"") | F5: =IFERROR(INDEX(Objekte!$N$2:$N$201,MATCH($A5,Objekte!$Z$2:$Z$201,0)),"") | G5: =IFERROR(INDEX(Objekte!$P$2:$P$201,MATCH($A5,Objekte!$Z$2:$Z$201,0)),"") | H5: =IFERROR(INDEX(Objekte!$E$2:$E$201,MATCH($A5,Objekte!$Z$2:$Z$201,0)),"") | I5: =IFERROR(INDEX(Objekte!$G$2:$G$201,MATCH($A5,Objekte!$Z$2:$Z$201,0)),"") | J5: =IFERROR(INDEX(Objekte!$I$2:$I$201,MATCH($A5,Objekte!$Z$2:$Z$201,0)),"") | K5: =IFERROR(INDEX(Objekte!$Q$2:$Q$201,MATCH($A5,Objekte!$Z$2:$Z$201,0)),"") | L5: =IFERROR(INDEX(Objekte!$V$2:$V$201,MATCH($A5,Objekte!$Z$2:$Z$201,0)),"") | M5: =IFERROR(INDEX(Objekte!$D$2:$D$201,MATCH($A5,Objekte!$Z$2:$Z$201,0)),"") | N5: =IFERROR(INDEX(Objekte!$U$2:$U$201,MATCH($A5,Objekte!$Z$2:$Z$201,0)),"") | O5: =IFERROR(INDEX(Objekte!$AF$2:$AF$201,MATCH($A5,Objekte!$Z$2:$Z$201,0)),"") | P5: =IFERROR(INDEX(Objekte!$C$2:$C$201,MATCH($A5,Objekte!$Z$2:$Z$201,0)),"") | Q5: =IFERROR(INDEX(Objekte!$AD$2:$AD$201,MATCH($A5,Objekte!$Z$2:$Z$201,0)),"") | R5: =IFERROR(INDEX(Objekte!$AB$2:$AB$201,MATCH($A5,Objekte!$Z$2:$Z$201,0)),"")
A6: 3 | B6: =IFERROR(INDEX(Objekte!$B$2:$B$201,MATCH($A6,Objekte!$Z$2:$Z$201,0)),"") | C6: =IFERROR(INDEX(Objekte!$X$2:$X$201,MATCH($A6,Objekte!$Z$2:$Z$201,0)),"") | D6: =IFERROR(INDEX(Objekte!$W$2:$W$201,MATCH($A6,Objekte!$Z$2:$Z$201,0)),"") | E6: =IFERROR(INDEX(Objekte!$L$2:$L$201,MATCH($A6,Objekte!$Z$2:$Z$201,0)),"") | F6: =IFERROR(INDEX(Objekte!$N$2:$N$201,MATCH($A6,Objekte!$Z$2:$Z$201,0)),"") | G6: =IFERROR(INDEX(Objekte!$P$2:$P$201,MATCH($A6,Objekte!$Z$2:$Z$201,0)),"") | H6: =IFERROR(INDEX(Objekte!$E$2:$E$201,MATCH($A6,Objekte!$Z$2:$Z$201,0)),"") | I6: =IFERROR(INDEX(Objekte!$G$2:$G$201,MATCH($A6,Objekte!$Z$2:$Z$201,0)),"") | J6: =IFERROR(INDEX(Objekte!$I$2:$I$201,MATCH($A6,Objekte!$Z$2:$Z$201,0)),"") | K6: =IFERROR(INDEX(Objekte!$Q$2:$Q$201,MATCH($A6,Objekte!$Z$2:$Z$201,0)),"") | L6: =IFERROR(INDEX(Objekte!$V$2:$V$201,MATCH($A6,Objekte!$Z$2:$Z$201,0)),"") | M6: =IFERROR(INDEX(Objekte!$D$2:$D$201,MATCH($A6,Objekte!$Z$2:$Z$201,0)),"") | N6: =IFERROR(INDEX(Objekte!$U$2:$U$201,MATCH($A6,Objekte!$Z$2:$Z$201,0)),"") | O6: =IFERROR(INDEX(Objekte!$AF$2:$AF$201,MATCH($A6,Objekte!$Z$2:$Z$201,0)),"") | P6: =IFERROR(INDEX(Objekte!$C$2:$C$201,MATCH($A6,Objekte!$Z$2:$Z$201,0)),"") | Q6: =IFERROR(INDEX(Objekte!$AD$2:$AD$201,MATCH($A6,Objekte!$Z$2:$Z$201,0)),"") | R6: =IFERROR(INDEX(Objekte!$AB$2:$AB$201,MATCH($A6,Objekte!$Z$2:$Z$201,0)),"")
A7: 4 | B7: =IFERROR(INDEX(Objekte!$B$2:$B$201,MATCH($A7,Objekte!$Z$2:$Z$201,0)),"") | C7: =IFERROR(INDEX(Objekte!$X$2:$X$201,MATCH($A7,Objekte!$Z$2:$Z$201,0)),"") | D7: =IFERROR(INDEX(Objekte!$W$2:$W$201,MATCH($A7,Objekte!$Z$2:$Z$201,0)),"") | E7: =IFERROR(INDEX(Objekte!$L$2:$L$201,MATCH($A7,Objekte!$Z$2:$Z$201,0)),"") | F7: =IFERROR(INDEX(Objekte!$N$2:$N$201,MATCH($A7,Objekte!$Z$2:$Z$201,0)),"") | G7: =IFERROR(INDEX(Objekte!$P$2:$P$201,MATCH($A7,Objekte!$Z$2:$Z$201,0)),"") | H7: =IFERROR(INDEX(Objekte!$E$2:$E$201,MATCH($A7,Objekte!$Z$2:$Z$201,0)),"") | I7: =IFERROR(INDEX(Objekte!$G$2:$G$201,MATCH($A7,Objekte!$Z$2:$Z$201,0)),"") | J7: =IFERROR(INDEX(Objekte!$I$2:$I$201,MATCH($A7,Objekte!$Z$2:$Z$201,0)),"") | K7: =IFERROR(INDEX(Objekte!$Q$2:$Q$201,MATCH($A7,Objekte!$Z$2:$Z$201,0)),"") | L7: =IFERROR(INDEX(Objekte!$V$2:$V$201,MATCH($A7,Objekte!$Z$2:$Z$201,0)),"") | M7: =IFERROR(INDEX(Objekte!$D$2:$D$201,MATCH($A7,Objekte!$Z$2:$Z$201,0)),"") | N7: =IFERROR(INDEX(Objekte!$U$2:$U$201,MATCH($A7,Objekte!$Z$2:$Z$201,0)),"") | O7: =IFERROR(INDEX(Objekte!$AF$2:$AF$201,MATCH($A7,Objekte!$Z$2:$Z$201,0)),"") | P7: =IFERROR(INDEX(Objekte!$C$2:$C$201,MATCH($A7,Objekte!$Z$2:$Z$201,0)),"") | Q7: =IFERROR(INDEX(Objekte!$AD$2:$AD$201,MATCH($A7,Objekte!$Z$2:$Z$201,0)),"") | R7: =IFERROR(INDEX(Objekte!$AB$2:$AB$201,MATCH($A7,Objekte!$Z$2:$Z$201,0)),"")
A8: 5 | B8: =IFERROR(INDEX(Objekte!$B$2:$B$201,MATCH($A8,Objekte!$Z$2:$Z$201,0)),"") | C8: =IFERROR(INDEX(Objekte!$X$2:$X$201,MATCH($A8,Objekte!$Z$2:$Z$201,0)),"") | D8: =IFERROR(INDEX(Objekte!$W$2:$W$201,MATCH($A8,Objekte!$Z$2:$Z$201,0)),"") | E8: =IFERROR(INDEX(Objekte!$L$2:$L$201,MATCH($A8,Objekte!$Z$2:$Z$201,0)),"") | F8: =IFERROR(INDEX(Objekte!$N$2:$N$201,MATCH($A8,Objekte!$Z$2:$Z$201,0)),"") | G8: =IFERROR(INDEX(Objekte!$P$2:$P$201,MATCH($A8,Objekte!$Z$2:$Z$201,0)),"") | H8: =IFERROR(INDEX(Objekte!$E$2:$E$201,MATCH($A8,Objekte!$Z$2:$Z$201,0)),"") | I8: =IFERROR(INDEX(Objekte!$G$2:$G$201,MATCH($A8,Objekte!$Z$2:$Z$201,0)),"") | J8: =IFERROR(INDEX(Objekte!$I$2:$I$201,MATCH($A8,Objekte!$Z$2:$Z$201,0)),"") | K8: =IFERROR(INDEX(Objekte!$Q$2:$Q$201,MATCH($A8,Objekte!$Z$2:$Z$201,0)),"") | L8: =IFERROR(INDEX(Objekte!$V$2:$V$201,MATCH($A8,Objekte!$Z$2:$Z$201,0)),"") | M8: =IFERROR(INDEX(Objekte!$D$2:$D$201,MATCH($A8,Objekte!$Z$2:$Z$201,0)),"") | N8: =IFERROR(INDEX(Objekte!$U$2:$U$201,MATCH($A8,Objekte!$Z$2:$Z$201,0)),"") | O8: =IFERROR(INDEX(Objekte!$AF$2:$AF$201,MATCH($A8,Objekte!$Z$2:$Z$201,0)),"") | P8: =IFERROR(INDEX(Objekte!$C$2:$C$201,MATCH($A8,Objekte!$Z$2:$Z$201,0)),"") | Q8: =IFERROR(INDEX(Objekte!$AD$2:$AD$201,MATCH($A8,Objekte!$Z$2:$Z$201,0)),"") | R8: =IFERROR(INDEX(Objekte!$AB$2:$AB$201,MATCH($A8,Objekte!$Z$2:$Z$201,0)),"")
A9: 6 | B9: =IFERROR(INDEX(Objekte!$B$2:$B$201,MATCH($A9,Objekte!$Z$2:$Z$201,0)),"") | C9: =IFERROR(INDEX(Objekte!$X$2:$X$201,MATCH($A9,Objekte!$Z$2:$Z$201,0)),"") | D9: =IFERROR(INDEX(Objekte!$W$2:$W$201,MATCH($A9,Objekte!$Z$2:$Z$201,0)),"") | E9: =IFERROR(INDEX(Objekte!$L$2:$L$201,MATCH($A9,Objekte!$Z$2:$Z$201,0)),"") | F9: =IFERROR(INDEX(Objekte!$N$2:$N$201,MATCH($A9,Objekte!$Z$2:$Z$201,0)),"") | G9: =IFERROR(INDEX(Objekte!$P$2:$P$201,MATCH($A9,Objekte!$Z$2:$Z$201,0)),"") | H9: =IFERROR(INDEX(Objekte!$E$2:$E$201,MATCH($A9,Objekte!$Z$2:$Z$201,0)),"") | I9: =IFERROR(INDEX(Objekte!$G$2:$G$201,MATCH($A9,Objekte!$Z$2:$Z$201,0)),"") | J9: =IFERROR(INDEX(Objekte!$I$2:$I$201,MATCH($A9,Objekte!$Z$2:$Z$201,0)),"") | K9: =IFERROR(INDEX(Objekte!$Q$2:$Q$201,MATCH($A9,Objekte!$Z$2:$Z$201,0)),"") | L9: =IFERROR(INDEX(Objekte!$V$2:$V$201,MATCH($A9,Objekte!$Z$2:$Z$201,0)),"") | M9: =IFERROR(INDEX(Objekte!$D$2:$D$201,MATCH($A9,Objekte!$Z$2:$Z$201,0)),"") | N9: =IFERROR(INDEX(Objekte!$U$2:$U$201,MATCH($A9,Objekte!$Z$2:$Z$201,0)),"") | O9: =IFERROR(INDEX(Objekte!$AF$2:$AF$201,MATCH($A9,Objekte!$Z$2:$Z$201,0)),"") | P9: =IFERROR(INDEX(Objekte!$C$2:$C$201,MATCH($A9,Objekte!$Z$2:$Z$201,0)),"") | Q9: =IFERROR(INDEX(Objekte!$AD$2:$AD$201,MATCH($A9,Objekte!$Z$2:$Z$201,0)),"") | R9: =IFERROR(INDEX(Objekte!$AB$2:$AB$201,MATCH($A9,Objekte!$Z$2:$Z$201,0)),"")
A10: 7 | B10: =IFERROR(INDEX(Objekte!$B$2:$B$201,MATCH($A10,Objekte!$Z$2:$Z$201,0)),"") | C10: =IFERROR(INDEX(Objekte!$X$2:$X$201,MATCH($A10,Objekte!$Z$2:$Z$201,0)),"") | D10: =IFERROR(INDEX(Objekte!$W$2:$W$201,MATCH($A10,Objekte!$Z$2:$Z$201,0)),"") | E10: =IFERROR(INDEX(Objekte!$L$2:$L$201,MATCH($A10,Objekte!$Z$2:$Z$201,0)),"") | F10: =IFERROR(INDEX(Objekte!$N$2:$N$201,MATCH($A10,Objekte!$Z$2:$Z$201,0)),"") | G10: =IFERROR(INDEX(Objekte!$P$2:$P$201,MATCH($A10,Objekte!$Z$2:$Z$201,0)),"") | H10: =IFERROR(INDEX(Objekte!$E$2:$E$201,MATCH($A10,Objekte!$Z$2:$Z$201,0)),"") | I10: =IFERROR(INDEX(Objekte!$G$2:$G$201,MATCH($A10,Objekte!$Z$2:$Z$201,0)),"") | J10: =IFERROR(INDEX(Objekte!$I$2:$I$201,MATCH($A10,Objekte!$Z$2:$Z$201,0)),"") | K10: =IFERROR(INDEX(Objekte!$Q$2:$Q$201,MATCH($A10,Objekte!$Z$2:$Z$201,0)),"") | L10: =IFERROR(INDEX(Objekte!$V$2:$V$201,MATCH($A10,Objekte!$Z$2:$Z$201,0)),"") | M10: =IFERROR(INDEX(Objekte!$D$2:$D$201,MATCH($A10,Objekte!$Z$2:$Z$201,0)),"") | N10: =IFERROR(INDEX(Objekte!$U$2:$U$201,MATCH($A10,Objekte!$Z$2:$Z$201,0)),"") | O10: =IFERROR(INDEX(Objekte!$AF$2:$AF$201,MATCH($A10,Objekte!$Z$2:$Z$201,0)),"") | P10: =IFERROR(INDEX(Objekte!$C$2:$C$201,MATCH($A10,Objekte!$Z$2:$Z$201,0)),"") | Q10: =IFERROR(INDEX(Objekte!$AD$2:$AD$201,MATCH($A10,Objekte!$Z$2:$Z$201,0)),"") | R10: =IFERROR(INDEX(Objekte!$AB$2:$AB$201,MATCH($A10,Objekte!$Z$2:$Z$201,0)),"")
A11: 8 | B11: =IFERROR(INDEX(Objekte!$B$2:$B$201,MATCH($A11,Objekte!$Z$2:$Z$201,0)),"") | C11: =IFERROR(INDEX(Objekte!$X$2:$X$201,MATCH($A11,Objekte!$Z$2:$Z$201,0)),"") | D11: =IFERROR(INDEX(Objekte!$W$2:$W$201,MATCH($A11,Objekte!$Z$2:$Z$201,0)),"") | E11: =IFERROR(INDEX(Objekte!$L$2:$L$201,MATCH($A11,Objekte!$Z$2:$Z$201,0)),"") | F11: =IFERROR(INDEX(Objekte!$N$2:$N$201,MATCH($A11,Objekte!$Z$2:$Z$201,0)),"") | G11: =IFERROR(INDEX(Objekte!$P$2:$P$201,MATCH($A11,Objekte!$Z$2:$Z$201,0)),"") | H11: =IFERROR(INDEX(Objekte!$E$2:$E$201,MATCH($A11,Objekte!$Z$2:$Z$201,0)),"") | I11: =IFERROR(INDEX(Objekte!$G$2:$G$201,MATCH($A11,Objekte!$Z$2:$Z$201,0)),"") | J11: =IFERROR(INDEX(Objekte!$I$2:$I$201,MATCH($A11,Objekte!$Z$2:$Z$201,0)),"") | K11: =IFERROR(INDEX(Objekte!$Q$2:$Q$201,MATCH($A11,Objekte!$Z$2:$Z$201,0)),"") | L11: =IFERROR(INDEX(Objekte!$V$2:$V$201,MATCH($A11,Objekte!$Z$2:$Z$201,0)),"") | M11: =IFERROR(INDEX(Objekte!$D$2:$D$201,MATCH($A11,Objekte!$Z$2:$Z$201,0)),"") | N11: =IFERROR(INDEX(Objekte!$U$2:$U$201,MATCH($A11,Objekte!$Z$2:$Z$201,0)),"") | O11: =IFERROR(INDEX(Objekte!$AF$2:$AF$201,MATCH($A11,Objekte!$Z$2:$Z$201,0)),"") | P11: =IFERROR(INDEX(Objekte!$C$2:$C$201,MATCH($A11,Objekte!$Z$2:$Z$201,0)),"") | Q11: =IFERROR(INDEX(Objekte!$AD$2:$AD$201,MATCH($A11,Objekte!$Z$2:$Z$201,0)),"") | R11: =IFERROR(INDEX(Objekte!$AB$2:$AB$201,MATCH($A11,Objekte!$Z$2:$Z$201,0)),"")
